File: example/4_Hall.dat
[Header]
TITLE, default name
FILEOPENTIME,22836721.98,10/21/2025,4:54 PM
BYAPP, Resistivity, 2.1, 1.0
INFO, APPNAME, PPMS MultiVu Application, 1.5.11
INFO, , Sample1 Name
INFO, 11, Sample1 Cross Section
INFO, 2.7, Sample1 Length
INFO, Ohm-cm, Sample1 Units
INFO, , Sample2 Name
INFO, 10, Sample2 Cross Section
INFO, 1, Sample2 Length
INFO, Ohm-cm, Sample2 Units
INFO, , Sample3 Name
INFO, 9, Sample3 Cross Section
INFO, 2.4, Sample3 Length
INFO, Ohm-cm, Sample3 Units
INFO, , Sample4 Name
INFO, 10, Sample4 Cross Section
INFO, 1, Sample4 Length
INFO, Ohm-cm, Sample4 Units
FIELDGROUP, Resistivity,2,3,4,5,6,7,8,9,10,11,12,13,14,15,16,17,18,19,20,21,22,23,24,25,26,27,28,29,30,31,32,33,34,35,36,37,38,39,40,41
STARTUPGROUP, Resistivity
STARTUPAXIS, X, 2, LINEAR, AUTO
STARTUPAXIS, Y1, 7, LINEAR, AUTO
STARTUPAXIS, Y2, 9, LINEAR, AUTO
STARTUPAXIS, Y3, 11, LINEAR, AUTO
PLOT_APPEARANCE, ALL, HORZ_GRID_ON, VERT_GRID_ON, MARKERS_AND_LINES, ALL_LINES
DATATYPE, TIME, 2
DATATYPE, COMMENT, 1
[Data]
Comment,Time Stamp (sec),Status (code),Temperature (K),Magnetic Field (Oe),Sample Position (deg),Bridge 1 Resistivity (Ohm-cm),Bridge 1 Excitation (uA),Bridge 2 Resistivity (Ohm-cm),Bridge 2 Excitation (uA),Bridge 3 Resistivity (Ohm-cm),Bridge 3 Excitation (uA),Bridge 4 Resistivity (Ohm-cm),Bridge 4 Excitation (uA),Bridge 1 Std. Dev. (Ohm-cm),Bridge 2 Std. Dev. (Ohm-cm),Bridge 3 Std. Dev. (Ohm-cm),Bridge 4 Std. Dev. (Ohm-cm),Number of Readings,Bridge 1 Resistance (Ohms),Bridge 2 Resistance (Ohms),Bridge 3 Resistance (Ohms),Bridge 4 Resistance (Ohms),Signal 1 Vin (V),Signal 2 Vin (V),Digital Inputs (code),Drive 1 Iout (mA),Drive 1 Ipower (watts),Drive 2 Iout (mA),Drive 2 Ipower (watts),Pressure (),Map 20 (),Map 21 (),Map 22 (),Map 23 (),Map 24 (),Map 25 (),Map 26 (),Map 27 (),Map 28 (),Map 29 ()
,22842873.97,4449,1.99994999170303,69883.600625,0,235573.159351852,0.100000001490116,7850.60908203125,0.100000001490116,22834.054921875,0.100000001490116,-1209.54666748047,0.100000001490116,158.056259689744,107.669981098216,20.8592083942175,710.674719977418,25,578225.0275,7850.60908203125,60890.813125,-1209.54666748047
,22843131.17,4449,2.00014996528625,66815.2775,0,225359.776481481,0.100000001490116,6848.65001953125,0.100000001490116,22405.6348828125,0.100000001490116,-839.912089233398,0.100000001490116,201.862329044042,277.252363714943,19.8919752056757,1044.56037967305,25,553155.815,6848.65001953125,59748.3596875,-839.912089233398
,22843390.03,4449,2.00119996070862,63816.87171875,0,215540.025555556,0.100000001490116,6415.6030078125,0.100000001490116,21893.2960546875,0.100000001490116,-414.513813476563,0.100000001490116,111.844599270534,155.36779155948,18.8018853097,586.998202293276,25,529052.79,6415.6030078125,58382.1228125,-414.513813476563
,22843649.06,4449,2.00099992752075,60822.13203125,0,206502.768796296,0.100000001490116,6044.27373046875,0.100000001490116,21421.51265625,0.100000001490116,-271.102156600952,0.100000001490116,143.307529847395,219.508614370452,38.5917731848327,641.600632144717,25,506870.4325,6044.27373046875,57124.03375,-271.102156600952
,22843910.11,4449,2.00014996528625,57811.2184375,0,198214.225,0.100000001490116,5267.1751171875,0.100000001490116,20891.7423046875,0.100000001490116,-302.26112487793,0.100000001490116,129.204778791927,151.776784563182,12.6689784576563,731.19735395956,25,486525.825,5267.1751171875,55711.3128125,-302.26112487793
,22844170.03,4449,2.0003000497818,54818.58140625,0,190740.181805556,0.100000001490116,5017.77171875,0.100000001490116,20364.6310546875,0.100000001490116,156.987224884033,0.100000001490116,86.3787439089733,199.665030352451,26.3215252513944,523.669505033518,25,468180.44625,5017.77171875,54305.6828125,156.987224884033
,22844430.66,4449,2.00005000829697,51820.93453125,0,183470.20337963,0.100000001490116,4216.0820703125,0.100000001490116,19823.1686132813,0.100000001490116,295.178161773682,0.100000001490116,155.610554722546,215.885016781425,20.3621023536784,540.966998419209,25,450335.95375,4216.0820703125,52861.78296875,295.178161773682
,22844691.72,4449,2.0001500248909,48825.496875,0,177204.80962963,0.100000001490116,3725.64599609375,0.100000001490116,19320.1160742187,0.100000001490116,500.645234489441,0.100000001490116,91.4039424246317,209.73764019682,27.402243221259,478.68910010551,25,434957.26,3725.64599609375,51520.30953125,500.645234489441
,22844953.75,4449,2.00059998035431,45824.0053125,0,171073.999351852,0.100000001490116,3877.72000976563,0.100000001490116,18876.6933984375,0.100000001490116,524.997880859375,0.100000001490116,99.4116344366737,239.745051729758,26.2788078395855,501.349147670153,25,419908.9075,3877.72000976563,50337.8490625,524.997880859375
,22845216.36,4449,1.99949997663498,42819.55203125,0,165812.961111111,0.100000001490116,3885.74615234375,0.100000001490116,18399.3260742187,0.100000001490116,818.639161987305,0.100000001490116,127.093385244258,199.501293900066,30.6625423108029,580.304863248015,25,406995.45,3885.74615234375,49064.86953125,818.639161987305
,22845479.50,4449,2.00034999847412,39817.60796875,0,160942.138703704,0.100000001490116,3594.56967773438,0.100000001490116,18007.8667382812,0.100000001490116,1139.11070709229,0.100000001490116,105.750831943423,158.77594636359,27.0869306289287,694.366646616693,25,395039.795,3594.56967773438,48020.97796875,1139.11070709229
,22845742.34,4449,1.99950003623962,36825.4775,0,156939.108842593,0.100000001490116,4051.30541992188,0.100000001490116,17684.7875390625,0.100000001490116,1371.76377960205,0.100000001490116,84.2251707895641,176.63385132732,18.735693372164,564.529933224728,25,385214.17625,4051.30541992188,47159.4334375,1371.76377960205
,22846006.13,4449,2.00005000829697,33824.85265625,0,153449.706666667,0.100000001490116,4234.524375,0.100000001490116,17431.6418554688,0.100000001490116,1588.31606079102,0.100000001490116,99.8918436716878,174.921879023641,19.433760293985,810.055711687924,25,376649.28,4234.524375,46484.37828125,1588.31606079102
,22846271.19,4449,1.99980002641678,30821.41265625,0,150442.053564815,0.100000001490116,4378.67125,0.100000001490116,17245.2244921875,0.100000001490116,1953.72061767578,0.100000001490116,69.3799700632083,119.302189304332,21.2469207594298,655.101348878137,25,369266.85875,4378.67125,45987.2653125,1953.72061767578
,22846536.33,4449,2.00075006484985,27821.70890625,0,148474.070046296,0.100000001490116,4629.9996875,0.100000001490116,17121.9367382812,0.100000001490116,2146.67109375,0.100000001490116,90.6883457178581,147.094699585832,36.2643967929593,698.065243916033,25,364436.35375,4629.9996875,45658.49796875,2146.67109375
,22846802.34,4449,2.00024998188019,24818.27640625,0,146927.340694444,0.100000001490116,4976.73439453125,0.100000001490116,17113.3127929688,0.100000001490116,2610.30010742188,0.100000001490116,137.04580405881,212.216814152027,38.0817323642247,736.175246053659,25,360639.83625,4976.73439453125,45635.50078125,2610.30010742188
,22847068.59,4449,2.00035005807877,21823.260703125,0,146358.36162037,0.100000001490116,5169.677421875,0.100000001490116,17151.8841210938,0.100000001490116,2853.06490478516,0.100000001490116,77.7352178326638,154.151214128916,27.2086106104156,695.670551618272,25,359243.25125,5169.677421875,45738.35765625,2853.06490478516
,22847336.30,4449,2.00045001506805,18817.288359375,0,146039.916203704,0.100000001490116,5622.28205078125,0.100000001490116,17233.6976367187,0.100000001490116,3027.91175292969,0.100000001490116,75.6669464050141,195.617207906826,14.1939988502078,771.836429141947,25,358461.6125,5622.28205078125,45956.52703125,3027.91175292969
,22847603.84,4449,2.00010001659393,15824.2369921875,0,146064.858194444,0.100000001490116,6240.16716796875,0.100000001490116,17339.5819921875,0.100000001490116,3191.03391601563,0.100000001490116,124.929932754903,151.009454756061,32.0744978558429,626.198409317071,25,358522.83375,6240.16716796875,46238.8853125,3191.03391601563
,22847872.89,4449,2.00014996528625,12823.328828125,0,146638.510231481,0.100000001490116,6715.91056640625,0.100000001490116,17458.6437890625,0.100000001490116,3920.56822265625,0.100000001490116,106.623457956735,185.755089032979,25.6557984051007,893.036164624641,25,359930.88875,6715.91056640625,46556.3834375,3920.56822265625
,22848142.63,4449,1.99965000152588,9827.3618359375,0,147489.151435185,0.100000001490116,7319.7922265625,0.100000001490116,17558.0441601562,0.100000001490116,3975.56107421875,0.100000001490116,93.0384052921908,194.462292536215,20.895507303327,863.836367844322,25,362018.82625,7319.7922265625,46821.45109375,3975.56107421875
,22848414.38,4449,2.00010001659393,6817.88298828125,0,148762.79662037,0.100000001490116,7876.61740234375,0.100000001490116,17613.4369335938,0.100000001490116,4836.1548046875,0.100000001490116,115.397438239715,208.35614115346,32.8674606409822,500.169022880714,25,365145.04625,7876.61740234375,46969.16515625,4836.1548046875
,22848684.48,4449,1.99955004453659,3828.5147265625,0,150143.76462963,0.100000001490116,8365.75384765625,0.100000001490116,17542.3426757812,0.100000001490116,4784.49046875,0.100000001490116,117.95790044143,243.7060375869,24.7696535365839,866.131850453028,25,368534.695,8365.75384765625,46779.58046875,4784.49046875
,22848954.84,4449,2.00050008296967,819.649553222656,0,146670.446388889,0.100000001490116,8848.6389453125,0.100000001490116,16717.0330078125,0.100000001490116,5111.25223632813,0.100000001490116,253.180823221831,237.553093002534,44.7058032459211,1171.1519019084,25,360009.2775,8848.6389453125,44578.7546875,5111.25223632813
,22849230.31,4449,2.0001500248909,-2167.34016601563,0,150381.033101852,0.100000001490116,9033.30359375,0.100000001490116,17301.3996679688,0.100000001490116,5446.5506640625,0.100000001490116,102.67098405562,208.410237388895,21.3787367632975,679.242113418446,25,369117.08125,9033.30359375,46137.06578125,5446.5506640625
,22849531.53,4449,1.99965000152588,-5170.23568359375,0,149579.25787037,0.100000001490116,9750.1476953125,0.100000001490116,17625.296484375,0.100000001490116,6130.623515625,0.100000001490116,159.2557897189,187.645216062311,24.8595149685452,906.157916198478,25,367149.0875,9750.1476953125,47000.790625,6130.623515625
,22849826.67,4449,1.99980002641678,-8176.062265625,0,148271.778009259,0.100000001490116,10115.6951171875,0.100000001490116,17642.0820117188,0.100000001490116,6213.23017578125,0.100000001490116,125.72188258316,252.156774297866,27.283119396513,1065.98221056242,25,363939.81875,10115.6951171875,47045.55203125,6213.23017578125
,22850120.47,4449,1.99940001964569,-11171.26203125,0,147258.923472222,0.100000001490116,10748.4751953125,0.100000001490116,17582.2583789062,0.100000001490116,6542.60111328125,0.100000001490116,96.1980086963147,194.021466471316,11.8274130033722,1138.19781441515,25,361453.72125,10748.4751953125,46886.02234375,6542.60111328125
,22850416.66,4449,2.00074994564056,-14180.6719140625,0,146642.356157407,0.100000001490116,11107.265,0.100000001490116,17482.1487304688,0.100000001490116,7173.3131640625,0.100000001490116,107.695127654306,199.656241661246,14.1033224027357,1100.91563036551,25,359940.32875,11107.265,46619.06328125,7173.3131640625
,22850712.42,4449,1.99844998121262,-17166.92515625,0,146469.861898148,0.100000001490116,11555.9771875,0.100000001490116,17394.01875,0.100000001490116,7438.155,0.100000001490116,104.626723718515,266.456577554084,16.0809084630281,983.016573490687,25,359516.93375,11555.9771875,46384.05,7438.155
,22851010.98,4449,1.99834996461868,-20173.580390625,0,146595.634675926,0.100000001490116,11928.236171875,0.100000001490116,17306.93390625,0.100000001490116,7628.3830078125,0.100000001490116,109.874623355502,188.599527769623,13.9540954222483,818.897237995127,25,359825.64875,11928.236171875,46151.82375,7628.3830078125
,22851309.61,4449,1.99930000305176,-23171.618828125,0,147447.219027778,0.100000001490116,12407.79390625,0.100000001490116,17254.8557226563,0.100000001490116,8055.413515625,0.100000001490116,100.365890507615,203.414423351698,7.38879271813559,717.558664465345,25,361915.90125,12407.79390625,46012.94859375,8055.413515625
,22851610.41,4449,1.99929994344711,-26179.501875,0,148648.904351852,0.100000001490116,13050.0883203125,0.100000001490116,17254.1303320313,0.100000001490116,8597.0129296875,0.100000001490116,112.705224224274,240.53136029612,16.7716742176414,812.11426082068,25,364865.4925,13050.0883203125,46011.01421875,8597.0129296875
,22851909.94,4449,2.00114989280701,-29165.65515625,0,150551.209722222,0.100000001490116,13588.6341796875,0.100000001490116,17325.6810351562,0.100000001490116,8976.82193359375,0.100000001490116,74.4943338838078,174.830423873122,9.49887702603951,703.922509952045,25,369534.7875,13588.6341796875,46201.81609375,8976.82193359375
,22852212.42,4449,1.99910002946854,-32173.599765625,0,153098.980833333,0.100000001490116,14129.2423046875,0.100000001490116,17481.3145898438,0.100000001490116,9083.61109375,0.100000001490116,89.4350734037622,220.7504052429,13.1208286536858,989.294417964335,25,375788.4075,14129.2423046875,46616.83890625,9083.61109375
,22852514.91,4449,1.99954998493195,-35172.22140625,0,155964.53125,0.100000001490116,15063.3336328125,0.100000001490116,17696.1933398438,0.100000001490116,9507.47447265625,0.100000001490116,94.8513515185087,149.999781826477,11.2265687861521,577.824176515706,25,382822.03125,15063.3336328125,47189.84890625,9507.47447265625
,22852817.66,4449,2.00095003843308,-38166.17046875,0,159531.390231481,0.100000001490116,15717.025078125,0.100000001490116,18001.1449804688,0.100000001490116,9940.64890625,0.100000001490116,85.0686890805156,162.06901677943,12.7188224954437,571.213949257286,25,391577.04875,15717.025078125,48003.05328125,9940.64890625
,22853122.39,4449,1.99874997138977,-41172.3809375,0,163724.719583333,0.100000001490116,16243.42609375,0.100000001490116,18370.5772265625,0.100000001490116,10428.1547265625,0.100000001490116,65.8151316465287,169.573688828222,10.2885555180084,628.956815251618,25,401869.76625,16243.42609375,48988.2059375,10428.1547265625
,22853427.36,4449,2.00124990940094,-44172.613125,0,168517.058009259,0.100000001490116,16954.23640625,0.100000001490116,18785.0513085937,0.100000001490116,10824.2718359375,0.100000001490116,102.720241627483,130.846315066311,13.3575684736975,761.914582627478,25,413632.77875,16954.23640625,50093.47015625,10824.2718359375
,22853732.09,4449,1.99945002794266,-47165.12046875,0,173726.796527778,0.100000001490116,17681.39875,0.100000001490116,19244.0025585938,0.100000001490116,11346.79609375,0.100000001490116,74.4937946372255,123.854813910553,13.1784124023274,589.717076091064,25,426420.31875,17681.39875,51317.34015625,11346.79609375
,22854039.09,4449,1.99989998340607,-50171.9978125,0,179485.60462963,0.100000001490116,18692.56125,0.100000001490116,19759.5614648438,0.100000001490116,11891.0031640625,0.100000001490116,117.062649345405,156.254087926985,21.5107960736033,569.706147012139,25,440555.575,18692.56125,52692.16390625,11891.0031640625
,22854346.38,4449,1.9998499751091,-53175.0240625,0,185781.858472222,0.100000001490116,19419.844765625,0.100000001490116,20245.866796875,0.100000001490116,12332.215703125,0.100000001490116,62.8401379260924,110.963121925956,15.5393297835081,491.491271401365,25,456010.01625,19419.844765625,53988.978125,12332.215703125
,22854652.72,4449,2.00024998188019,-56164.73,0,192683.471851852,0.100000001490116,19985.639296875,0.100000001490116,20734.0365820313,0.100000001490116,12736.451796875,0.100000001490116,223.002098706552,268.315012560182,14.022040611549,345.309487775118,25,472950.34,19985.639296875,55290.76421875,12736.451796875
,22854962.13,4449,2.00040006637573,-59174.485,0,200111.946527778,0.100000001490116,20858.483515625,0.100000001490116,21224.579296875,0.100000001490116,13539.247578125,0.100000001490116,107.774207420682,223.091531582741,11.801824216139,419.291138956572,25,491183.86875,20858.483515625,56598.878125,13539.247578125
,22855271.05,4449,2.00034999847412,-62173.09890625,0,208406.481759259,0.100000001490116,21994.5815625,0.100000001490116,21694.5589453125,0.100000001490116,13699.7478125,0.100000001490116,126.05847222055,139.511765252236,7.93220005537713,520.313741851333,25,511543.1825,21994.5815625,57852.1571875,13699.7478125
,22855580.52,4449,1.99945002794266,-65172.58796875,0,217079.109907407,0.100000001490116,22782.996875,0.100000001490116,22171.1240039063,0.100000001490116,14571.52,0.100000001490116,130.154650297558,236.712942749779,10.1001309961143,699.999568248982,25,532830.5425,22782.996875,59122.99734375,14571.52
,22855889.69,4449,2.00029993057251,-68161.534375,0,226773.913055556,0.100000001490116,23627.163515625,0.100000001490116,22624.3229296875,0.100000001490116,15051.2055078125,0.100000001490116,132.663194224346,319.953510279721,13.3386760507785,639.214808784579,25,556626.8775,23627.163515625,60331.5278125,15051.2055078125
,22856298.77,4449,2.99975001811981,-66637.5665625,0,203171.153981482,0.100000001490116,21956.3225,0.100000001490116,22334.4042773438,0.100000001490116,14524.7825390625,0.100000001490116,475.650252910231,105.700368549808,28.8175073738797,504.101804063865,25,498692.8325,21956.3225,59558.41140625,14524.7825390625
,22856511.33,4449,2.99940001964569,-56040.168125,0,177551.31625,0.100000001490116,19033.961015625,0.100000001490116,20620.4297460937,0.100000001490116,12645.33078125,0.100000001490116,347.485463454465,177.444742267596,33.9767582655947,519.812040223828,25,435807.77625,19033.961015625,54987.81265625,12645.33078125
,22856725.67,4449,3.00050008296967,-45353.48796875,0,157536.688935185,0.100000001490116,16546.6816015625,0.100000001490116,18821.3251171875,0.100000001490116,10760.5145703125,0.100000001490116,282.099626792004,72.9105391105289,32.2756441285859,550.177367175364,25,386680.96375,16546.6816015625,50190.2003125,10760.5145703125
,22856941.05,4449,3.00075006484985,-34628.55796875,0,143968.50875,0.100000001490116,13982.218359375,0.100000001490116,17485.7142773438,0.100000001490116,9096.74021484375,0.100000001490116,156.646670499278,77.770529924779,22.3300115537122,727.288595351153,25,353377.24875,13982.218359375,46628.57140625,9096.74021484375
,22857155.27,4449,2.99965000152588,-23969.239375,0,137425.552916667,0.100000001490116,11919.313125,0.100000001490116,17059.6546289063,0.100000001490116,8023.93234375,0.100000001490116,70.6391795549885,149.221218969481,10.1577271810416,830.02589140539,25,337317.26625,11919.313125,45492.41234375,8023.93234375
,22857371.08,4449,3.00090003013611,-13235.7086328125,0,137471.777361111,0.100000001490116,10319.5216015625,0.100000001490116,17311.6039453125,0.100000001490116,7003.3490234375,0.100000001490116,76.7575727324102,125.440374935352,19.2864541182452,994.537675667357,25,337430.72625,10319.5216015625,46164.2771875,7003.3490234375
,22857585.05,4449,3.00114989280701,-2546.61904296875,0,139951.015925926,0.100000001490116,8837.8964453125,0.100000001490116,17186.1145898438,0.100000001490116,5886.83875976562,0.100000001490116,134.083155764471,112.120164784038,36.9239379154763,968.569207874656,25,343516.13,8837.8964453125,45829.63890625,5886.83875976562
,22857806.66,4449,3.00020003318787,8224.3325390625,0,137928.191805556,0.100000001490116,6877.0477734375,0.100000001490116,17365.77,0.100000001490116,4058.78788818359,0.100000001490116,92.7829463465753,128.15730177785,23.4501650706828,1255.87777061936,25,338551.01625,6877.0477734375,46308.72,4058.78788818359
,22858024.41,4449,2.99995005130768,18733.86109375,0,135709.085925926,0.100000001490116,5130.4852734375,0.100000001490116,16987.0055859375,0.100000001490116,3277.12163696289,0.100000001490116,50.9652233108184,96.3741897301251,23.7786131084917,1189.80422478013,25,333104.12,5130.4852734375,45298.6815625,3277.12163696289
,22858242.39,4449,3.00059998035431,29263.868359375,0,138715.278472222,0.100000001490116,3695.04495117187,0.100000001490116,16948.918828125,0.100000001490116,2407.29220947266,0.100000001490116,144.437731119959,88.8945339319759,18.7321272019354,923.526169552974,25,340482.95625,3695.04495117187,45197.116875,2407.29220947266
,22858460.22,4449,2.99990010261536,39767.411875,0,148286.859722222,0.100000001490116,3084.98755859375,0.100000001490116,17753.8728515625,0.100000001490116,1042.62764404297,0.100000001490116,245.658663256576,56.5838629044756,29.9686593480972,691.580057209782,25,363976.8375,3084.98755859375,47343.6609375,1042.62764404297
,22858677.33,4449,2.99925005435944,50213.3628125,0,164286.185046296,0.100000001490116,3073.90915039063,0.100000001490116,19273.9037109375,0.100000001490116,849.612465820313,0.100000001490116,291.500141562531,57.6038035017524,36.5547974583406,847.363140405996,25,403247.90875,3073.90915039063,51397.0765625,849.612465820313
,22858896.56,4449,2.9996999502182,60740.50015625,0,185956.103055556,0.100000001490116,3909.08907226563,0.100000001490116,20975.0814257812,0.100000001490116,-424.333311309814,0.100000001490116,400.483303822169,95.2438359751054,29.5481970040939,1101.93520716586,25,456437.7075,3909.08907226563,55933.55046875,-424.333311309814
,22859261.45,4449,5.0008499622345,69572.75625,0,192568.359907407,0.100000001490116,4196.29987304688,0.100000001490116,22263.5703515625,0.100000001490116,-625.256150856018,0.100000001490116,491.303622553922,42.8239120636654,24.2824504548181,922.215759589001,25,472667.7925,4196.29987304688,59369.5209375,-625.256150856018
,22859473.25,4449,5.00074982643127,58927.34109375,0,168926.842638889,0.100000001490116,3113.15862304688,0.100000001490116,20667.9882421875,0.100000001490116,-3.0283288192749,0.100000001490116,336.060239869758,49.212357244861,30.1383345293788,776.794717215849,25,414638.61375,3113.15862304688,55114.6353125,-3.0283288192749
,22859687.00,4449,4.99959993362427,48239.1571875,0,150257.64875,0.100000001490116,2526.60806640625,0.100000001490116,18930.4280859375,0.100000001490116,709.605764465332,0.100000001490116,246.873898822888,35.2949365552275,36.2714913253034,671.839137874537,25,368814.22875,2526.60806640625,50481.1415625,709.605764465332
,22859900.50,4449,5.00025010108948,37574.53625,0,136821.665648148,0.100000001490116,2604.33134765625,0.100000001490116,17458.5674414062,0.100000001490116,1498.51305084229,0.100000001490116,167.609695452756,35.0632376584875,24.219929993709,737.115017256743,25,335834.9975,2604.33134765625,46556.17984375,1498.51305084229
,22860113.20,4449,5.00055003166199,26959.6284375,0,129158.055277778,0.100000001490116,3467.21302734375,0.100000001490116,16772.7660351563,0.100000001490116,2230.71214111328,0.100000001490116,80.6696962649376,60.1806621789835,17.7198120754236,657.956336517986,25,317024.3175,3467.21302734375,44727.37609375,2230.71214111328
,22860325.80,4449,4.99945020675659,16357.043125,0,127414.173842593,0.100000001490116,4950.73734375,0.100000001490116,16917.5017382813,0.100000001490116,3670.76286132812,0.100000001490116,33.0081927504447,66.5034062932809,23.3703841060708,813.298800973487,25,312743.88125,4950.73734375,45113.33796875,3670.76286132812
,22860536.56,4449,4.99969983100891,5836.181796875,0,129277.018240741,0.100000001490116,6615.14705078125,0.100000001490116,17162.50546875,0.100000001490116,4654.28298828125,0.100000001490116,32.9530959149554,50.0875472347264,25.337806052847,970.901856452125,25,317316.3175,6615.14705078125,45766.68125,4654.28298828125
,22860753.06,4449,4.99920010566711,-4871.58365234375,0,128943.618425926,0.100000001490116,8540.8324609375,0.100000001490116,17163.6914648437,0.100000001490116,5767.11317382812,0.100000001490116,26.3890500363789,71.6365139554412,23.858793542618,1206.46699383309,25,316497.9725,8540.8324609375,45769.84390625,5767.11317382812
,22860970.19,4449,4.99970006942749,-15351.5789453125,0,126620.831944444,0.100000001490116,10171.3823046875,0.100000001490116,17026.4771484375,0.100000001490116,7386.4546484375,0.100000001490116,33.4097446365896,56.6035809195853,10.7226262660207,817.466299505718,25,310796.5875,10171.3823046875,45403.9390625,7386.4546484375
,22861187.20,4449,4.99944996833801,-25861.49109375,0,127630.482222222,0.100000001490116,11677.160546875,0.100000001490116,16866.5208398438,0.100000001490116,8201.1879296875,0.100000001490116,81.3233634265739,58.0139149625197,13.1920493220225,601.805589835776,25,313274.82,11677.160546875,44977.38890625,8201.1879296875
,22861404.66,4449,4.99990010261536,-36378.231875,0,134307.25662037,0.100000001490116,13598.2945703125,0.100000001490116,17455.1494921875,0.100000001490116,9532.4250390625,0.100000001490116,138.002827836517,54.974317096881,19.4749506066471,629.53708044768,25,329663.26625,13598.2945703125,46547.0653125,9532.4250390625
,22861620.67,4449,4.99910020828247,-46807.3715625,0,146656.237546296,0.100000001490116,15955.690234375,0.100000001490116,18833.4943359375,0.100000001490116,11269.709140625,0.100000001490116,251.316288932542,53.4647810013008,28.3329898120354,571.730406396704,25,359974.40125,15955.690234375,50222.6515625,11269.709140625
,22861838.61,4449,5.00049996376038,-57309.57953125,0,164136.203101852,0.100000001490116,18515.49578125,0.100000001490116,20592.1034179687,0.100000001490116,12895.8446875,0.100000001490116,338.09603739179,51.0270284762554,27.5283007866128,404.659152773626,25,402879.77125,18515.49578125,54912.27578125,12895.8446875
,22862057.34,4449,4.99979996681213,-67830.66375,0,187096.012175926,0.100000001490116,21245.171640625,0.100000001490116,22282.01296875,0.100000001490116,14891.05703125,0.100000001490116,412.312103266668,70.4789267725803,28.9277993960568,571.405522578963,25,459235.66625,21245.171640625,59418.70125,14891.05703125
,22862456.50,4449,10.0006999969482,-62306.71515625,0,164481.142222222,0.100000001490116,19276.34515625,0.100000001490116,21684.8179101562,0.100000001490116,13910.125703125,0.100000001490116,337.141819116759,49.8481829050219,26.9781401819429,461.555102396552,25,403726.44,19276.34515625,57826.18109375,13910.125703125
,22862670.23,4449,10.0001001358032,-51652.79796875,0,146720.703148148,0.100000001490116,16738.6909375,0.100000001490116,19888.8754101563,0.100000001490116,12303.7598828125,0.100000001490116,249.387103474915,47.7944433467284,31.7656898300853,514.980614108913,25,360132.635,16738.6909375,53037.00109375,12303.7598828125
,22862880.91,4449,10.0003499984741,-41151.6328125,0,133309.37125,0.100000001490116,14455.732734375,0.100000001490116,18198.5568164063,0.100000001490116,10554.1985546875,0.100000001490116,200.735839524846,52.9514361362941,25.8631250445603,462.083067560981,25,327213.91125,14455.732734375,48529.48484375,10554.1985546875
,22863092.23,4449,10.0001001358032,-30642.09703125,0,124657.829490741,0.100000001490116,12355.05671875,0.100000001490116,17171.3258789062,0.100000001490116,9031.9962890625,0.100000001490116,103.865444134001,39.7269036153666,13.7535333363477,568.305759586085,25,305978.30875,12355.05671875,45790.20234375,9031.9962890625
,22863305.30,4449,9.9997501373291,-20035.659921875,0,121328.42587963,0.100000001490116,10494.407109375,0.100000001490116,17009.5676953125,0.100000001490116,7801.1815625,0.100000001490116,42.3685355867981,50.9471816379761,8.3094319403664,636.54813406361,25,297806.13625,10494.407109375,45358.8471875,7801.1815625
,22863520.72,4449,10.0000500679016,-9329.3525,0,121767.569305556,0.100000001490116,8879.4778125,0.100000001490116,17248.1908007812,0.100000001490116,6512.415,0.100000001490116,24.9445207698969,48.6203739385434,18.1359457853221,815.690035509124,25,298884.03375,8879.4778125,45995.17546875,6512.415
,22863736.34,4449,9.99949979782104,1541.30848144531,0,117861.649074074,0.100000001490116,6875.42990234375,0.100000001490116,16733.0933203125,0.100000001490116,5335.22936523438,0.100000001490116,455.293138792746,27.6541431562019,55.0073848778718,647.446772860456,25,289296.775,6875.42990234375,44621.5821875,5335.22936523438
,22863954.64,4449,10.0004997253418,11934.185859375,0,121347.925416667,0.100000001490116,5419.314140625,0.100000001490116,17136.04875,0.100000001490116,4047.49829101563,0.100000001490116,27.9222905619586,39.0011014176273,17.092542492341,855.532442284952,25,297853.99875,5419.314140625,45696.13,4047.49829101563
,22864172.94,4449,10.0002999305725,22480.152578125,0,121538.499907407,0.100000001490116,3821.96569335938,0.100000001490116,16866.8980664063,0.100000001490116,2981.6900390625,0.100000001490116,48.9282212894231,50.762801072048,15.5898196039321,679.587612461366,25,298321.7725,3821.96569335938,44978.39484375,2981.6900390625
,22864389.39,4449,10,32934.8128125,0,126271.332916667,0.100000001490116,2648.59765625,0.100000001490116,17159.53734375,0.100000001490116,2098.94086914063,0.100000001490116,125.690111881473,41.97784908712,16.6137918644516,682.291277988434,25,309938.72625,2648.59765625,45758.76625,2098.94086914063
,22864607.66,4449,10.0003499984741,43445.35328125,0,136697.886111111,0.100000001490116,2106.75586914062,0.100000001490116,18332.1375585937,0.100000001490116,1356.49743202209,0.100000001490116,200.611007297536,36.9837037000583,27.5036505281068,712.125916065828,25,335531.175,2106.75586914062,48885.70015625,1356.49743202209
,22864825.70,4449,10.0004501342773,53930.1215625,0,151706.750046296,0.100000001490116,2190.69502929688,0.100000001490116,20063.3823632812,0.100000001490116,598.371871643066,0.100000001490116,262.694594787298,44.001417585736,32.1891654444805,394.377992253322,25,372371.11375,2190.69502929688,53502.35296875,598.371871643066
,22865045.03,4449,10.0004501342773,64457.91890625,0,171223.688472222,0.100000001490116,3008.55518554687,0.100000001490116,21771.5738085937,0.100000001490116,-103.154619750977,0.100000001490116,355.135180817827,40.7966013607099,29.9152949047695,563.327533538814,25,420276.32625,3008.55518554687,58057.53015625,-103.154619750977
,22865499.27,4449,20.00119972229,63684.22265625,0,1109293.43148148,0.0270000007003546,81736.5078125,0.100000001490116,54711.50109375,0.100000001490116,8498.51091796875,0.100000001490116,3583.96547552919,371.537673141295,154.227934144718,279.752345195509,25,2722811.15,81736.5078125,145897.33625,8498.51091796875
,22865713.20,4449,20.0009508132935,46732.46109375,0,896893.539259259,0.034000001847744,59731.39375,0.100000001490116,46474.6681640625,0.100000001490116,8393.419453125,0.100000001490116,3169.4684821128,278.151537769681,128.857500123943,289.997079265799,25,2201465.96,59731.39375,123932.4484375,8393.419453125
,22865928.59,4449,19.9994993209839,29709.99359375,0,762262.726296296,0.0419999994337559,48458.90671875,0.100000001490116,42047.7162890625,0.100000001490116,9573.8233203125,0.100000001490116,299.971317191653,51.6751145557671,9.44049412555511,309.671922465444,25,1871008.51,48458.90671875,112127.2434375,9573.8233203125
,22866142.72,4449,19.9997491836548,12764.7769921875,0,746918.429074074,0.0419999994337559,50607.31984375,0.100000001490116,43575.5220703125,0.100000001490116,13012.8037109375,0.100000001490116,157.828428187512,117.544958532801,26.1515377179717,259.135654427036,25,1833345.235,50607.31984375,116201.3921875,13012.8037109375
,22866355.03,4449,20.0002994537354,-4033.52685546875,0,755883.111296296,0.0439999997615814,56696.8721875,0.100000001490116,44057.9131640625,0.100000001490116,16795.0274609375,0.100000001490116,986.823066474617,187.754280977422,77.6367790665302,414.73181076631,25,1855349.455,56696.8721875,117487.7684375,16795.0274609375
,22866568.47,4449,19.9999008178711,-20510.55875,0,790682.479074074,0.0390000008046627,65713.8915625,0.100000001490116,44835.4020703125,0.100000001490116,20172.933125,0.100000001490116,373.774989856186,84.2080913812659,37.0557879920503,397.708084732709,25,1940766.085,65713.8915625,119561.0721875,20172.933125
,22866781.05,4449,20.000750541687,-36970.8634375,0,828215.575,0.0403200002014637,75565.7221875,0.100000001490116,45464.8269140625,0.100000001490116,23167.463359375,0.100000001490116,2286.90454043784,311.349012623501,68.0896697465342,354.046081442078,25,2032892.775,75565.7221875,121239.5384375,23167.463359375
,22866992.59,4449,20.001350402832,-53342.3471875,0,1008024.92592593,0.0320000015199184,98912.926875,0.100000001490116,52482.046875,0.100000001490116,28248.69109375,0.100000001490116,3931.91998197177,542.05390179506,162.054547461581,299.02479923748,25,2474243,98912.926875,139952.125,28248.69109375
,22867207.42,4449,19.9995994567871,-69841.2778125,0,1300194.55296296,0.0216799999773502,137535.54875,0.100000001490116,66606.560625,0.100000001490116,34870.45984375,0.100000001490116,3934.31975335392,566.104339684189,244.155907023663,254.479162603954,25,3191386.63,137535.54875,177617.495,34870.45984375
,22867642.73,4449,30.0001001358032,-54314.83296875,0,2284046.70592593,0.00499999988824129,282078.6225,0.100000001490116,166461.87796875,0.100000001490116,68848.97875,0.100000001490116,9209.06519197041,1448.87712206408,997.840500134031,357.801536293474,25,5606296.46,282078.6225,443898.34125,68848.97875
,22867857.27,4449,30.0003004074097,-37383.76515625,0,1780523.80814815,0.0120000001043081,201429.18875,0.100000001490116,118957.06734375,0.100000001490116,50660.51578125,0.100000001490116,5526.97708554157,1080.4541574027,543.452771183396,279.282045527795,25,4370376.62,201429.18875,317218.84625,50660.51578125
,22868079.64,4449,30.0003004074097,-19827.31,0,1494047.89111111,0.017000000923872,147798.23875,0.100000001490116,98124.632578125,0.100000001490116,39784.044375,0.100000001490116,3333.54543980111,647.215743209252,134.723045045278,220.726537870337,25,3667208.46,147798.23875,261665.686875,39784.044375
,22868300.22,4449,29.9998502731323,-2367.74075683594,0,1384309.10037037,0.0199999995529652,121678.7659375,0.100000001490116,91429.172109375,0.100000001490116,32625.094375,0.100000001490116,1112.85744444218,254.220993142762,263.255293860827,261.52102970351,25,3397849.61,121678.7659375,243811.125625,32625.094375
,22868521.02,4449,30.0000495910645,14713.769453125,0,1447233.97703704,0.0199999995529652,119616.039375,0.100000001490116,96108.0665625,0.100000001490116,29287.317109375,0.100000001490116,2089.05225718553,152.40551242646,74.1959088130726,96.0643496834773,25,3552301.58,119616.039375,256288.1775,29287.317109375
,22868742.89,4449,30.0002508163452,31864.397109375,0,1672242.93296296,0.0149999996647239,143062.944375,0.100000001490116,109085.15203125,0.100000001490116,29445.884921875,0.100000001490116,4819.97724730634,694.63741054847,380.861994071524,108.19189903003,25,4104596.29,143062.944375,290893.73875,29445.884921875
,22868958.73,4449,30,48532.6225,0,2076100.72592593,0.00700000021606684,200378.141875,0.100000001490116,146735.42015625,0.100000001490116,37098.4771875,0.100000001490116,6976.96072687635,1242.77904907053,828.886377115282,233.579168779885,25,5095883.6,200378.141875,391294.45375,37098.4771875
,22869177.84,4449,30.0001497268677,65404.018125,0,2479876.59333333,0.00700000021606684,292544.94875,0.100000001490116,214021.1240625,0.100000001490116,53712.55359375,0.100000001490116,8752.05711449323,1618.21362216182,1301.77658224172,397.114511363966,25,6086969.82,292544.94875,570722.9975,53712.55359375
,22871410.27,4449,39.9979991912842,-58847.949375,0,1981657.63481481,0.00999999977648258,264057.5525,0.100000001490116,214044.0459375,0.100000001490116,90172.4125,0.100000001490116,5757.70308936075,1134.25936833986,1170.58162960235,543.716325937008,25,4864068.74,264057.5525,570784.1225,90172.4125
,22871627.64,4449,40.0002498626709,-41690.899375,0,1642550.74703704,0.0149999996647239,199522.245625,0.100000001490116,154089.75890625,0.100000001490116,66647.1525,0.100000001490116,4833.67639844687,955.026227433123,743.706888801602,473.632729003899,25,4031715.47,199522.245625,410906.02375,66647.1525
,22871847.86,4449,39.9997501373291,-24317.30515625,0,1397159.17814815,0.0199999995529652,150705.2025,0.100000001490116,120952.39546875,0.100000001490116,51107.43,0.100000001490116,2750.51404601649,665.895467178309,292.825979515697,505.760178182598,25,3429390.71,150705.2025,322539.72125,51107.43
,22872068.39,4449,40.0014514923096,-6890.54533203125,0,1282076.13925926,0.0219999998807907,121341.434375,0.100000001490116,110873.01234375,0.100000001490116,42535.9578125,0.100000001490116,1145.28361107836,410.808416687825,123.031943220686,396.241805591752,25,3146914.16,121341.434375,295661.36625,42535.9578125
,22872287.44,4449,40.0012493133545,10198.852890625,0,1296262.83518519,0.0219999998807907,108911.2634375,0.100000001490116,112015.27171875,0.100000001490116,37692.50984375,0.100000001490116,1208.87391124996,87.6279353631007,96.4352386763271,218.221750316073,25,3181736.05,108911.2634375,298707.39125,37692.50984375
,22872504.23,4449,39.9985980987549,26949.17015625,0,1426429.37962963,0.0199999995529652,113020.066875,0.100000001490116,123696.6525,0.100000001490116,37266.90609375,0.100000001490116,3148.88571305577,279.299855586014,349.35617745456,352.616789638049,25,3501235.75,113020.066875,329857.74,37266.90609375
,22872722.11,4449,40.0009994506836,43780.99703125,0,1687914.74296296,0.0149999996647239,140755.165,0.100000001490116,159176.71875,0.100000001490116,44652.71234375,0.100000001490116,5029.54525903638,717.958527251845,811.349214549903,346.481732793838,25,4143063.46,140755.165,424471.25,44652.71234375
,22872942.14,4449,40.0006999969482,60740.13203125,0,2049122.76148148,0.00700000021606684,191833.106875,0.100000001490116,221089.2365625,0.100000001490116,61047.06796875,0.100000001490116,5478.04913631155,907.139970882703,1173.9498926644,391.829639164615,25,5029664.96,191833.106875,589571.2975,61047.06796875
,22873383.05,4449,50.0004997253418,63482.1953125,0,1796638.03407407,0.0120000001043081,148348.765,0.100000001490116,273341.5921875,0.100000001490116,74037.3690625,0.100000001490116,4347.7191386961,669.300892886608,1310.26266369726,379.739870348166,25,4409929.72,148348.765,728910.9125,74037.3690625
,22873600.16,4449,50.0004005432129,46302.84,0,1540800.75518518,0.0160400003194809,115573.0603125,0.100000001490116,202956.9815625,0.100000001490116,55840.7153125,0.100000001490116,6563.03859051029,397.23957403148,968.62791459564,327.775259841328,25,3781965.49,115573.0603125,541218.6175,55840.7153125
,22873814.33,4449,50.0000495910645,29351.837890625,0,1332711.9137037,0.0199999995529652,98813.198125,0.100000001490116,156846.534375,0.100000001490116,45897.864375,0.100000001490116,2821.43967446939,194.31020081719,530.611040134368,258.296217136377,25,3271201.97,98813.198125,418257.425,45897.864375
,22874032.00,4449,50.0002002716064,12138.9983984375,0,1216167.62666667,0.0240000002086163,99665.2425,0.100000001490116,137425.64859375,0.100000001490116,44905.6515625,0.100000001490116,1007.06294194701,191.327601263312,155.98576589593,221.85586626857,25,2985138.72,99665.2425,366468.39625,44905.6515625
,22874246.75,4449,50.0000991821289,-4825.84541015625,0,1191677.12481481,0.0240000002086163,113380.0046875,0.100000001490116,133871.62921875,0.100000001490116,49954.3384375,0.100000001490116,860.009746691453,354.445855828036,151.49177438293,335.341650027997,25,2925025.67,113380.0046875,356991.01125,49954.3384375
,22874469.94,4449,50.0000495910645,-22064.55046875,0,1264708.91148148,0.0240000002086163,139875.804375,0.100000001490116,145699.31765625,0.100000001490116,59928.58546875,0.100000001490116,1745.17623083176,505.202273342427,324.967964712126,268.04316247222,25,3104285.51,139875.804375,388531.51375,59928.58546875
,22874686.06,4449,49.9999008178711,-38803.81890625,0,1430930.60814815,0.0199999995529652,177336.350625,0.100000001490116,179487.22125,0.100000001490116,76473.538125,0.100000001490116,3276.02767131516,745.397074660243,754.434623004256,428.231637997534,25,3512284.22,177336.350625,478632.59,76473.538125
,22874900.31,4449,50.0000495910645,-55381.204375,0,1658669.95555556,0.0149999996647239,222969.381875,0.100000001490116,237672.8184375,0.100000001490116,100307.334375,0.100000001490116,3670.95424007367,804.593446704026,1116.97094599642,459.657742655498,25,4071280.8,222969.381875,633794.1825,100307.334375
,22875135.36,4369,50.0002002716064,-69999.890625,0,1876826.46148148,0.0120000001043081,268316.92125,0.100000001490116,305109.7603125,0.100000001490116,125665.4815625,0.100000001490116,1581.41495912655,164.993031348832,35.6382541561979,175.627734989035,25,4606755.86,268316.92125,813626.0275,125665.4815625
,22877568.56,4449,99.9991493225098,53292.319375,0,606146.676666667,0.0540000014007092,29518.78625,0.100000001490116,337559.6353125,0.0926000010967255,84320.771875,0.100000001490116,519.145638731433,96.0782272312267,879.565662728292,188.062897503966,25,1487814.57,29518.78625,900159.0275,84320.771875
,22877786.80,4449,100.0006980896,36042.11328125,0,575254.400925926,0.0560000017285347,33699.39515625,0.100000001490116,292421.7871875,0.100000001490116,78764.1328125,0.100000001490116,510.075653807768,172.312431561661,649.04139127242,145.48590831094,25,1411988.075,33699.39515625,779791.4325,78764.1328125
,22878004.11,4449,100.000949859619,18849.115625,0,554533.72537037,0.0590000003576279,41161.27703125,0.100000001490116,261949.86375,0.100000001490116,79187.1365625,0.100000001490116,237.999729316622,230.734374761824,267.902886103811,177.555237057258,25,1361128.235,41161.27703125,698532.97,79187.1365625
,22878216.83,4449,99.9991989135742,1932.15048828125,0,545934.648518518,0.0610000006854534,51830.4921875,0.100000001490116,251165.8078125,0.100000001490116,86785.6203125,0.100000001490116,79.7191684163118,224.704430264071,44.5866270946102,276.700408234621,25,1340021.41,51830.4921875,669775.4875,86785.6203125
,22878432.39,4449,100.000297546387,-14763.6662890625,0,550719.463148148,0.0610000006854534,63872.04265625,0.100000001490116,257774.019375,0.100000001490116,100120.1484375,0.100000001490116,212.615845175351,208.207033156597,298.366354770332,306.411536240096,25,1351765.955,63872.04265625,687397.385,100120.1484375
,22878647.95,4449,100.001003265381,-31459.245234375,0,566714.343148148,0.0610000006854534,75994.933125,0.100000001490116,282379.899375,0.100000001490116,118233.6128125,0.100000001490116,349.087280377399,256.014324400284,540.026702573861,323.870665506136,25,1391026.115,75994.933125,753013.065,118233.6128125
,22878865.30,4449,99.999698638916,-48273.07046875,0,594335.968518519,0.0590000003576279,87577.3909375,0.100000001490116,323360.55375,0.100000001490116,140208.45,0.100000001490116,537.131569200541,264.825661934244,718.901711347249,399.358347972745,25,1458824.65,87577.3909375,862294.81,140208.45
,22879085.30,4449,100.000152587891,-65268.1690625,0,627212.049444444,0.0558400017023087,98388.9046875,0.100000001490116,371400.4453125,0.0880799996852875,163067.541875,0.100000001490116,570.384761475135,214.931973176909,801.227784323426,410.343435281399,25,1539520.485,98388.9046875,990401.1875,163067.541875
,22879724.72,4449,150.005249023438,-59235.24671875,0,247686.09962963,0.100000001490116,36079.94515625,0.100000001490116,239367.2990625,0.100000001490116,97458.138125,0.100000001490116,137.819450303497,69.1065185684487,249.462307531064,174.570848838271,25,607956.79,36079.94515625,638312.7975,97458.138125
,22879939.06,4449,150.003852844238,-42313.0565625,0,240606.716574074,0.100000001490116,32871.531171875,0.100000001490116,224308.8815625,0.100000001490116,88883.5715625,0.100000001490116,99.6900119763961,116.987443503867,235.591149753602,166.769434286806,25,590580.1225,32871.531171875,598157.0175,88883.5715625
,22880158.28,4449,150.002647399902,-25020.587421875,0,235002.39787037,0.100000001490116,29602.32015625,0.100000001490116,211798.5234375,0.100000001490116,79775.7621875,0.100000001490116,63.0840105887996,70.7538941511347,158.596297364471,135.429132957412,25,576824.0675,29602.32015625,564796.0625,79775.7621875
,22880375.72,4449,150.001899719238,-7834.01234375,0,231608.915185185,0.100000001490116,25888.4059375,0.100000001490116,204525.4621875,0.100000001490116,71239.4246875,0.100000001490116,40.0040286896378,91.4732895517375,69.8244336207358,194.146609415888,25,568494.61,25888.4059375,545401.2325,71239.4246875
,22880593.63,4449,150.000350952148,9181.0430859375,0,231838.943518518,0.100000001490116,22365.125625,0.100000001490116,204900.7921875,0.100000001490116,64315.09125,0.100000001490116,36.0126807873315,59.5594546629308,66.9974367021471,147.858733487705,25,569059.225,22365.125625,546402.1125,64315.09125
,22880808.34,4449,150.000747680664,25769.485390625,0,235327.567037037,0.100000001490116,19574.958125,0.100000001490116,212207.1309375,0.100000001490116,60475.05515625,0.100000001490116,55.3683322310713,79.7157552557368,159.405975108236,94.8166191222211,25,577622.21,19574.958125,565885.6825,60475.05515625
,22881025.56,4449,150.002052307129,42542.84421875,0,240888.739259259,0.100000001490116,17593.68171875,0.100000001490116,224485.4484375,0.100000001490116,59266.6059375,0.100000001490116,108.710229937286,63.0363171308568,234.926492906605,104.28006099198,25,591272.36,17593.68171875,598627.8625,59266.6059375
,22881240.98,4449,150.001304626465,59156.32359375,0,247769.098703704,0.100000001490116,15944.7438671875,0.100000001490116,239216.7384375,0.100000001490116,59770.25359375,0.100000001490116,135.171623041899,49.7057255838383,240.019612734825,95.5005622617537,25,608160.515,15944.7438671875,637911.3025,59770.25359375
,22881896.86,4449,200.012252807617,65748.02515625,0,131471.936851852,0.100000001490116,10525.8715625,0.100000001490116,144133.05609375,0.100000001490116,40926.68296875,0.100000001490116,48.7669182397833,68.5889700661175,89.1366188640211,81.1857659519599,25,322703.845,10525.8715625,384354.81625,40926.68296875
,22882114.36,4449,200.00350189209,48529.45359375,0,128522.23287037,0.100000001490116,11008.5181640625,0.100000001490116,138485.95640625,0.100000001490116,40288.154375,0.100000001490116,61.071673685154,71.9813134481346,53.4392022469647,68.159210467856,25,315463.6625,11008.5181640625,369295.88375,40288.154375
,22882332.38,4449,200.001098632813,31279.929765625,0,126256.118796296,0.100000001490116,11732.0892578125,0.100000001490116,133962.526875,0.100000001490116,40413.87578125,0.100000001490116,44.3166272349121,64.771206500228,84.7166859239187,79.1885355134262,25,309901.3825,11732.0892578125,357233.405,40413.87578125
,22882553.91,4449,199.999649047852,13749.88484375,0,124664.675972222,0.100000001490116,12406.85671875,0.100000001490116,130794.245625,0.100000001490116,41281.4803125,0.100000001490116,25.3022060985474,51.9847492632222,49.0814536252322,57.1511600974876,25,305995.11375,12406.85671875,348784.655,41281.4803125
,22882767.42,4449,200.001602172852,-3210.09444335938,0,124140.453148148,0.100000001490116,13312.2827734375,0.100000001490116,129784.798125,0.100000001490116,43111.41921875,0.100000001490116,28.2921544755353,71.7358363882831,24.210543515747,81.5965614389669,25,304708.385,13312.2827734375,346092.795,43111.41921875
,22882981.00,4449,200.001655578613,-19659.128046875,0,125044.016574074,0.100000001490116,14439.50828125,0.100000001490116,131592.01546875,0.100000001490116,45759.3334375,0.100000001490116,25.2980891897074,146.134047119056,68.5325400200187,76.3310850321093,25,306926.2225,14439.50828125,350912.04125,45759.3334375
,22883196.55,4449,199.997497558594,-36342.7446875,0,126708.244259259,0.100000001490116,15606.1895703125,0.100000001490116,135211.03078125,0.100000001490116,48728.61421875,0.100000001490116,56.8613065730636,60.730034890738,69.8251994030786,66.8868824785756,25,311011.145,15606.1895703125,360562.74875,48728.61421875
,22883413.66,4449,200.001052856445,-53138.6084375,0,129001.536990741,0.100000001490116,16565.30828125,0.100000001490116,139963.7259375,0.100000001490116,51630.4390625,0.100000001490116,33.3128591092276,91.3040723994552,93.1178371055688,105.529704063689,25,316640.13625,16565.30828125,373236.6025,51630.4390625
,22883632.83,4449,199.999198913574,-69847.0628125,0,131696.955601852,0.100000001490116,17529.649609375,0.100000001490116,145313.195625,0.100000001490116,54437.64109375,0.100000001490116,52.9576245172198,74.3250476864913,61.0598766188963,102.3166837868,25,323256.16375,17529.649609375,387501.855,54437.64109375
,22886415.66,4449,300.006149291992,55620.13046875,0,45602.3691087963,0.100000001490116,4262.65310546875,0.100000001490116,49850.31234375,0.100000001490116,18933.965234375,0.100000001490116,17.8851046645142,25.1344149282209,42.9503191950509,552.397734527624,25,111933.0878125,4262.65310546875,132934.16625,18933.965234375
,22886633.33,4449,300.003707885742,38399.011875,0,45040.9730324074,0.100000001490116,4342.19751953125,0.100000001490116,48787.303359375,0.100000001490116,19029.73515625,0.100000001490116,11.1881061155342,19.2839241487086,25.0730810684332,535.810638546199,25,110555.115625,4342.19751953125,130099.475625,19029.73515625
,22886846.81,4449,299.997604370117,21519.935859375,0,44417.9096064815,0.100000001490116,4750.022265625,0.100000001490116,48014.201015625,0.100000001490116,18412.4809375,0.100000001490116,25.6593577492558,58.4707142363862,24.7261895559911,755.95886028274,25,109025.778125,4750.022265625,128037.869375,18412.4809375
,22887059.59,4449,299.997039794922,4645.96203125,0,44500.8970949074,0.100000001490116,4390.48572265625,0.100000001490116,47760.45,0.100000001490116,18269.3422265625,0.100000001490116,16.3522524772402,37.1783492070295,39.3373047122284,904.735805567133,25,109229.4746875,4390.48572265625,127361.2,18269.3422265625
,22887276.80,4449,300.00129699707,-12271.923671875,0,44481.8923032407,0.100000001490116,4792.34435546875,0.100000001490116,47850.5520703125,0.100000001490116,19076.441171875,0.100000001490116,23.0662050346623,44.930089344323,20.2746045903079,917.849202085941,25,109182.8265625,4792.34435546875,127601.4721875,19076.441171875
,22887489.47,4449,299.998413085938,-28754.771640625,0,44802.1993171296,0.100000001490116,5015.115234375,0.100000001490116,48396.428203125,0.100000001490116,19676.3025,0.100000001490116,18.4849431844596,45.7162312508371,25.9643307906779,536.315173561101,25,109969.0346875,5015.115234375,129057.141875,19676.3025
,22887703.16,4449,300.000335693359,-45298.465,0,45361.8840277778,0.100000001490116,5070.08375,0.100000001490116,49232.964140625,0.100000001490116,20328.270234375,0.100000001490116,22.1120591653945,24.9607038590715,21.8695522282221,589.206497400279,25,111342.80625,5070.08375,131287.904375,20328.270234375
,22887922.56,4449,299.997009277344,-62259.4190625,0,45823.0552083333,0.100000001490116,5634.06361328125,0.100000001490116,50335.820625,0.100000001490116,20835.40140625,0.100000001490116,18.1677769495195,34.3993587854617,38.0668642645772,585.642273416802,25,112474.771875,5634.06361328125,134228.855,20835.40140625
,22888037.23,4433,299.999801635742,-69999.965,0,46166.1948611111,0.100000001490116,5673.4508203125,0.100000001490116,50947.89046875,0.100000001490116,21331.407421875,0.100000001490116,20.426860991621,35.7174773210622,48.6143078264574,634.583546713177,25,113317.02375,5673.4508203125,135861.04125,21331.407421875